Workbook

Sheet README
A1: Karni Jewellery — Master Product Database
A2: 8 linked sheets · 474 variants · 163 designs · live analytics
A4: The 8 sheets
A5: DESIGNS — one row per design concept (163). Story, materials, cost, marketing copy, base price live here once.
A6: VARIANTS — your 474 SKUs, enriched. Stock, barcode, channel flags, prices in 4 currencies, auto-margins & sales pulled from Transactions.
A7: TRANSACTIONS — log every sale / restock / return here. This powers all sales & profit analytics.
A8: DASHBOARD — live KPIs: inventory health, sales, profit, channel split, catalog breakdown.
A9: SHOPIFY EXPORT — auto-built, Shopify CSV schema. Save as CSV to import.
A10: ETSY EXPORT — auto-built, Etsy listing reference.
A11: DROPDOWNS — control lists, FX rates (USD/EUR/RUB), channel list, cleanup log.
A12: README — this sheet.
A14: Colour coding (industry standard)
... A33: Full log on the Dropdowns sheet (right side). All 474 original rows preserved.

Sheet Designs
A1: IDENTIFICATION | H1: STORY & CULTURE | L1: MATERIALS & CRAFT | W1: COST · PRICE · MARGIN | AF1: MARKETING / DIGITAL | AN1: LIFECYCLE
A2: DesignID | B2: Design name (EN) | C2: Design name (HY) | D2: Category | E2: Collection | F2: Subcollection | G2: Variant count | H2: Motif / Symbol | I2: Cultural meaning (EN) | J2: Cultural meaning (HY) | K2: Inspiration source | L2: Metal | M2: Plating / Finish | N2: Enamel type | O2: Stones / Inlays | P2: Base weight (g) | Q2: Length (mm) | R2: Width (mm) | S2: Chain length (mm) | T2: Clasp | U2: Handmade | V2: Production time (days) | W2: Base price (AMD) | X2: Materials cost (AMD) | Y2: Labor cost (AMD) | Z2: Packaging cost (AMD) | AA2: Total cost (AMD) | AB2: Gross margin % | AC2: Markup x | AD2: Status | AE2: Made to order | AF2: Primary image URL | AG2: IG post URL | AH2: Caption (EN) | AI2: Caption (HY) | AJ2: Hashtags | AK2: SEO title | AL2: SEO description | AM2: Hero product? | AN2: Launch date | AO2: Discontinued date | AP2: Notes
A3: DSGN-PEND-ALPHA-AYB | B3: Bird Letter Pendant | D3: Pendant | E3: Alphabet | F3: Ա | G3: 3 | H3: Armenian bird letter (թռչնագիր) | I3: Bird letters are an ornamental medieval Armenian script where each letter is formed from stylised birds, used in illuminated manuscripts. | L3: 925 Silver Gold-Plated | M3: 24k Gold Plate | N3: Hot / Vitreous | U3: Yes | W3: 19000 | AA3: =IF(COUNT(X3,Y3,Z3)=0,"",SUM(X3,Y3,Z3)) | AB3: =IFERROR(IF(OR(W3="",AA3=""),"",(W3-AA3)/W3),"") | AC3: =IFERROR(IF(OR(AA3="",AA3=0),"",W3/AA3),"") | AD3: Active | AE3: No | AL3: No
A4: DSGN-PEND-ALPHA-BEN | B4: Bird Letter Pendant | D4: Pendant | E4: Alphabet | F4: Բ | G4: 3 | H4: Armenian bird letter (թռչնագիր) | I4: Bird letters are an ornamental medieval Armenian script where each letter is formed from stylised birds, used in illuminated manuscripts. | L4: 925 Silver Gold-Plated | M4: 24k Gold Plate | N4: Hot / Vitreous | U4: Yes | W4: 19000 | AA4: =IF(COUNT(X4,Y4,Z4)=0,"",SUM(X4,Y4,Z4)) | AB4: =IFERROR(IF(OR(W4="",AA4=""),"",(W4-AA4)/W4),"") | AC4: =IFERROR(IF(OR(AA4="",AA4=0),"",W4/AA4),"") | AD4: Active | AE4: No | AL4: No
A5: DSGN-PEND-ALPHA-GIM | B5: Bird Letter Pendant | D5: Pendant | E5: Alphabet | F5: Գ | G5: 3 | H5: Armenian bird letter (թռչնագիր) | I5: Bird letters are an ornamental medieval Armenian script where each letter is formed from stylised birds, used in illuminated manuscripts. | L5: 925 Silver Gold-Plated | M5: 24k Gold Plate | N5: Hot / Vitreous | U5: Yes | W5: 19000 | AA5: =IF(COUNT(X5,Y5,Z5)=0,"",SUM(X5,Y5,Z5)) | AB5: =IFERROR(IF(OR(W5="",AA5=""),"",(W5-AA5)/W5),"") | AC5: =IFERROR(IF(OR(AA5="",AA5=0),"",W5/AA5),"") | AD5: Active | AE5: No | AL5: No
A6: DSGN-PEND-ALPHA-DA | B6: Bird Letter Pendant | D6: Pendant | E6: Alphabet | F6: Դ | G6: 3 | H6: Armenian bird letter (թռչնագիր) | I6: Bird letters are an ornamental medieval Armenian script where each letter is formed from stylised birds, used in illuminated manuscripts. | L6: 925 Silver Gold-Plated | M6: 24k Gold Plate | N6: Hot / Vitreous | U6: Yes | W6: 19000 | AA6: =IF(COUNT(X6,Y6,Z6)=0,"",SUM(X6,Y6,Z6)) | AB6: =IFERROR(IF(OR(W6="",AA6=""),"",(W6-AA6)/W6),"") | AC6: =IFERROR(IF(OR(AA6="",AA6=0),"",W6/AA6),"") | AD6: Active | AE6: No | AL6: No
A7: DSGN-PEND-ALPHA-YECH | B7: Bird Letter Pendant | D7: Pendant | E7: Alphabet | F7: Ե | G7: 3 | H7: Armenian bird letter (թռչնագիր) | I7: Bird letters are an ornamental medieval Armenian script where each letter is formed from stylised birds, used in illuminated manuscripts. | L7: 925 Silver Gold-Plated | M7: 24k Gold Plate | N7: Hot / Vitreous | U7: Yes | W7: 19000 | AA7: =IF(COUNT(X7,Y7,Z7)=0,"",SUM(X7,Y7,Z7)) | AB7: =IFERROR(IF(OR(W7="",AA7=""),"",(W7-AA7)/W7),"") | AC7: =IFERROR(IF(OR(AA7="",AA7=0),"",W7/AA7),"") | AD7: Active | AE7: No | AL7: No
A8: DSGN-PEND-ALPHA-ZA | B8: Bird Letter Pendant | D8: Pendant | E8: Alphabet | F8: Զ | G8: 3 | H8: Armenian bird letter (թռչնագիր) | I8: Bird letters are an ornamental medieval Armenian script where each letter is formed from stylised birds, used in illuminated manuscripts. | L8: 925 Silver Gold-Plated | M8: 24k Gold Plate | N8: Hot / Vitreous | U8: Yes | W8: 19000 | AA8: =IF(COUNT(X8,Y8,Z8)=0,"",SUM(X8,Y8,Z8)) | AB8: =IFERROR(IF(OR(W8="",AA8=""),"",(W8-AA8)/W8),"") | AC8: =IFERROR(IF(OR(AA8="",AA8=0),"",W8/AA8),"") | AD8: Active | AE8: No | AL8: No
A9: DSGN-PEND-ALPHA-E | B9: Bird Letter Pendant | D9: Pendant | E9: Alphabet | F9: Է | G9: 3 | H9: Armenian bird letter (թռչնագիր) | I9: Bird letters are an ornamental medieval Armenian script where each letter is formed from stylised birds, used in illuminated manuscripts. | L9: 925 Silver Gold-Plated | M9: 24k Gold Plate | N9: Hot / Vitreous | U9: Yes | W9: 19000 | AA9: =IF(COUNT(X9,Y9,Z9)=0,"",SUM(X9,Y9,Z9)) | AB9: =IFERROR(IF(OR(W9="",AA9=""),"",(W9-AA9)/W9),"") | AC9: =IFERROR(IF(OR(AA9="",AA9=0),"",W9/AA9),"") | AD9: Active | AE9: No | AL9: No
A10: DSGN-PEND-ALPHA-YT | B10: Bird Letter Pendant | D10: Pendant | E10: Alphabet | F10: Ը | G10: 3 | H10: Armenian bird letter (թռչնագիր) | I10: Bird letters are an ornamental medieval Armenian script where each letter is formed from stylised birds, used in illuminated manuscripts. | L10: 925 Silver Gold-Plated | M10: 24k Gold Plate | N10: Hot / Vitreous | U10: Yes | W10: 19000 | AA10: =IF(COUNT(X10,Y10,Z10)=0,"",SUM(X10,Y10,Z10)) | AB10: =IFERROR(IF(OR(W10="",AA10=""),"",(W10-AA10)/W10),"") | AC10: =IFERROR(IF(OR(AA10="",AA10=0),"",W10/AA10),"") | AD10: Active | AE10: No | AL10: No
A11: DSGN-PEND-ALPHA-TO | B11: Bird Letter Pendant | D11: Pendant | E11: Alphabet | F11: Թ | G11: 3 | H11: Armenian bird letter (թռչնագիր) | I11: Bird letters are an ornamental medieval Armenian script where each letter is formed from stylised birds, used in illuminated manuscripts. | L11: 925 Silver Gold-Plated | M11: 24k Gold Plate | N11: Hot / Vitreous | U11: Yes | W11: 19000 | AA11: =IF(COUNT(X11,Y11,Z11)=0,"",SUM(X11,Y11,Z11)) | AB11: =IFERROR(IF(OR(W11="",AA11=""),"",(W11-AA11)/W11),"") | AC11: =IFERROR(IF(OR(AA11="",AA11=0),"",W11/AA11),"") | AD11: Active | AE11: No | AL11: No
A12: DSGN-PEND-ALPHA-ZHE | B12: Bird Letter Pendant | D12: Pendant | E12: Alphabet | F12: Ժ | G12: 3 | H12: Armenian bird letter (թռչնագիր) | I12: Bird letters are an ornamental medieval Armenian script where each letter is formed from stylised birds, used in illuminated manuscripts. | L12: 925 Silver Gold-Plated | M12: 24k Gold Plate | N12: Hot / Vitreous | U12: Yes | W12: 19000 | AA12: =IF(COUNT(X12,Y12,Z12)=0,"",SUM(X12,Y12,Z12)) | AB12: =IFERROR(IF(OR(W12="",AA12=""),"",(W12-AA12)/W12),"") | AC12: =IFERROR(IF(OR(AA12="",AA12=0),"",W12/AA12),"") | AD12: Active | AE12: No | AL12: No
A13: DSGN-PEND-ALPHA-INI | B13: Bird Letter Pendant | D13: Pendant | E13: Alphabet | F13: Ի | G13: 3 | H13: Armenian bird letter (թռչնագիր) | I13: Bird letters are an ornamental medieval Armenian script where each letter is formed from stylised birds, used in illuminated manuscripts. | L13: 925 Silver Gold-Plated | M13: 24k Gold Plate | N13: Hot / Vitreous | U13: Yes | W13: 19000 | AA13: =IF(COUNT(X13,Y13,Z13)=0,"",SUM(X13,Y13,Z13)) | AB13: =IFERROR(IF(OR(W13="",AA13=""),"",(W13-AA13)/W13),"") | AC13: =IFERROR(IF(OR(AA13="",AA13=0),"",W13/AA13),"") | AD13: Active | AE13: No | AL13: No
A14: DSGN-PEND-ALPHA-LYUN | B14: Bird Letter Pendant | D14: Pendant | E14: Alphabet | F14: Լ | G14: 3 | H14: Armenian bird letter (թռչնագիր) | I14: Bird letters are an ornamental medieval Armenian script where each letter is formed from stylised birds, used in illuminated manuscripts. | L14: 925 Silver Gold-Plated | M14: 24k Gold Plate | N14: Hot / Vitreous | U14: Yes | W14: 19000 | AA14: =IF(COUNT(X14,Y14,Z14)=0,"",SUM(X14,Y14,Z14)) | AB14: =IFERROR(IF(OR(W14="",AA14=""),"",(W14-AA14)/W14),"") | AC14: =IFERROR(IF(OR(AA14="",AA14=0),"",W14/AA14),"") | AD14: Active | AE14: No | AL14: No
... A116: DSGN-BRCH-ALPHA-FEH | B116: Bird Letter Brooch | D116: Brooch | E116: Alphabet | F116: Ֆ | G116: 1 | H116: Armenian bird letter (թռչնագիր) | I116: Bird letters are an ornamental medieval Armenian script where each letter is formed from stylised birds, used in illuminated manuscripts. | L116: 925 Silver Gold-Plated | M116: 24k Gold Plate | N116: Hot / Vitreous | U116: Yes | W116: 25000 | AA116: =IF(COUNT(X116,Y116,Z116)=0,"",SUM(X116,Y116,Z116)) | AB116: =IFERROR(IF(OR(W116="",AA116=""),"",(W116-AA116)/W116),"") | AC116: =IFERROR(IF(OR(AA116="",AA116=0),"",W116/AA116),"") | AD116: Active | AE116: No | AL116: No
A117: DSGN-EARRNG-MARASH-S | B117: Marash Earrings | D117: Earring | E117: Marash | G117: 5 | H117: Marash embroidery motif | I117: Marash-work is a distinctive Armenian embroidery style from Cilician Marash, known for its interlaced geometric patterns. | L117: 925 Silver Gold-Plated | M117: 24k Gold Plate | N117: Hot / Vitreous | U117: Yes | W117: 13000 | AA117: =IF(COUNT(X117,Y117,Z117)=0,"",SUM(X117,Y117,Z117)) | AB117: =IFERROR(IF(OR(W117="",AA117=""),"",(W117-AA117)/W117),"") | AC117: =IFERROR(IF(OR(AA117="",AA117=0),"",W117/AA117),"") | AD117: Active | AE117: No | AL117: No
A118: DSGN-EARRNG-MARASH-M | B118: Marash Earrings | D118: Earring | E118: Marash | G118: 4 | H118: Marash embroidery motif | I118: Marash-work is a distinctive Armenian embroidery style from Cilician Marash, known for its interlaced geometric patterns. | L118: 925 Silver Gold-Plated | M118: 24k Gold Plate | N118: Hot / Vitreous | U118: Yes | W118: 27000 | AA118: =IF(COUNT(X118,Y118,Z118)=0,"",SUM(X118,Y118,Z118)) | AB118: =IFERROR(IF(OR(W118="",AA118=""),"",(W118-AA118)/W118),"") | AC118: =IFERROR(IF(OR(AA118="",AA118=0),"",W118/AA118),"") | AD118: Active | AE118: No | AL118: No
A119: DSGN-EARRNG-VAN-S | B119: Van Earrings | D119: Earring | E119: Van | G119: 5 | H119: Van / Vaspurakan motif | I119: Motifs from the Van/Vaspurakan region, echoing the ornament of the Lake Van heartland of historic Armenia. | L119: 925 Silver Gold-Plated | M119: 24k Gold Plate | N119: Hot / Vitreous | U119: Yes | W119: 13000 | AA119: =IF(COUNT(X119,Y119,Z119)=0,"",SUM(X119,Y119,Z119)) | AB119: =IFERROR(IF(OR(W119="",AA119=""),"",(W119-AA119)/W119),"") | AC119: =IFERROR(IF(OR(AA119="",AA119=0),"",W119/AA119),"") | AD119: Active | AE119: No | AL119: No
A120: DSGN-EARRNG-VAN-M | B120: Van Earrings | D120: Earring | E120: Van | G120: 4 | H120: Van / Vaspurakan motif | I120: Motifs from the Van/Vaspurakan region, echoing the ornament of the Lake Van heartland of historic Armenia. | L120: 925 Silver Gold-Plated | M120: 24k Gold Plate | N120: Hot / Vitreous | U120: Yes | W120: 27000 | AA120: =IF(COUNT(X120,Y120,Z120)=0,"",SUM(X120,Y120,Z120)) | AB120: =IFERROR(IF(OR(W120="",AA120=""),"",(W120-AA120)/W120),"") | AC120: =IFERROR(IF(OR(AA120="",AA120=0),"",W120/AA120),"") | AD120: Active | AE120: No | AL120: No
A121: DSGN-EARRNG-ARTSAKHIKHACHANAKHSH-S | B121: Artsakhi Khachanakhsh Earrings | D121: Earring | E121: Artsakhi Khachanakhsh | G121: 6 | H121: Artsakh cross-ornament (khachanakhsh) | I121: Cross-ornament patterns from Artsakh, carrying the carved cross-stone heritage of the region. | L121: 925 Silver Gold-Plated | M121: 24k Gold Plate | N121: Hot / Vitreous | U121: Yes | W121: 13000 | AA121: =IF(COUNT(X121,Y121,Z121)=0,"",SUM(X121,Y121,Z121)) | AB121: =IFERROR(IF(OR(W121="",AA121=""),"",(W121-AA121)/W121),"") | AC121: =IFERROR(IF(OR(AA121="",AA121=0),"",W121/AA121),"") | AD121: Active | AE121: No | AL121: No
A122: DSGN-EARRNG-ARTSAKHIKHACHANAKHSH-M | B122: Artsakhi Khachanakhsh Earrings | D122: Earring | E122: Artsakhi Khachanakhsh | G122: 4 | H122: Artsakh cross-ornament (khachanakhsh) | I122: Cross-ornament patterns from Artsakh, carrying the carved cross-stone heritage of the region. | L122: 925 Silver Gold-Plated | M122: 24k Gold Plate | N122: Hot / Vitreous | U122: Yes | W122: 27000 | AA122: =IF(COUNT(X122,Y122,Z122)=0,"",SUM(X122,Y122,Z122)) | AB122: =IFERROR(IF(OR(W122="",AA122=""),"",(W122-AA122)/W122),"") | AC122: =IFERROR(IF(OR(AA122="",AA122=0),"",W122/AA122),"") | AD122: Active | AE122: No | AL122: No
A123: DSGN-EARRNG-VISHAB-S | B123: Vishab Earrings | D123: Earring | E123: Vishab | G123: 5 | H123: Vishap (dragon-stone) motif | I123: Vishaps are ancient Armenian dragon-stones (vishapakar) found in the highlands, among the oldest carved monuments in the region. | L123: 925 Silver Gold-Plated | M123: 24k Gold Plate | N123: Hot / Vitreous | U123: Yes | W123: 13000 | AA123: =IF(COUNT(X123,Y123,Z123)=0,"",SUM(X123,Y123,Z123)) | AB123: =IFERROR(IF(OR(W123="",AA123=""),"",(W123-AA123)/W123),"") | AC123: =IFERROR(IF(OR(AA123="",AA123=0),"",W123/AA123),"") | AD123: Active | AE123: No | AL123: No
A124: DSGN-EARRNG-VISHAB-M | B124: Vishab Earrings | D124: Earring | E124: Vishab | G124: 4 | H124: Vishap (dragon-stone) motif | I124: Vishaps are ancient Armenian dragon-stones (vishapakar) found in the highlands, among the oldest carved monuments in the region. | L124: 925 Silver Gold-Plated | M124: 24k Gold Plate | N124: Hot / Vitreous | U124: Yes | W124: 27000 | AA124: =IF(COUNT(X124,Y124,Z124)=0,"",SUM(X124,Y124,Z124)) | AB124: =IFERROR(IF(OR(W124="",AA124=""),"",(W124-AA124)/W124),"") | AC124: =IFERROR(IF(OR(AA124="",AA124=0),"",W124/AA124),"") | AD124: Active | AE124: No | AL124: No
A125: DSGN-EARRNG-VISHABAREVAGORG-S | B125: Արեւագորգի Վիշապ | D125: Earring | E125: Vishab Arevagorg | G125: 5 | H125: Vishap + Arevagorg (sun-carpet) motif | I125: Combines the vishap (dragon) motif with the arevagorg (sun-carpet) — an Armenian solar ornament symbolising life and eternity. | L125: 925 Silver Gold-Plated | M125: 24k Gold Plate | N125: Hot / Vitreous | U125: Yes | W125: 13000 | AA125: =IF(COUNT(X125,Y125,Z125)=0,"",SUM(X125,Y125,Z125)) | AB125: =IFERROR(IF(OR(W125="",AA125=""),"",(W125-AA125)/W125),"") | AC125: =IFERROR(IF(OR(AA125="",AA125=0),"",W125/AA125),"") | AD125: Active | AE125: No | AL125: No
A126: DSGN-EARRNG-VISHABAREVAGORG-M | B126: Արեւագորգի Վիշապ | D126: Earring | E126: Vishab Arevagorg | G126: 4 | H126: Vishap + Arevagorg (sun-carpet) motif | I126: Combines the vishap (dragon) motif with the arevagorg (sun-carpet) — an Armenian solar ornament symbolising life and eternity. | L126: 925 Silver Gold-Plated | M126: 24k Gold Plate | N126: Hot / Vitreous | U126: Yes | W126: 27000 | AA126: =IF(COUNT(X126,Y126,Z126)=0,"",SUM(X126,Y126,Z126)) | AB126: =IFERROR(IF(OR(W126="",AA126=""),"",(W126-AA126)/W126),"") | AC126: =IFERROR(IF(OR(AA126="",AA126=0),"",W126/AA126),"") | AD126: Active | AE126: No | AL126: No
A127: DSGN-EARRNG2-MARASH | B127: Marash Earrings (2 pcs) | D127: earrings 2 pcs. | E127: Marash | G127: 4 | H127: Marash embroidery motif | I127: Marash-work is a distinctive Armenian embroidery style from Cilician Marash, known for its interlaced geometric patterns. | L127: 925 Silver Gold-Plated | M127: 24k Gold Plate | N127: Hot / Vitreous | U127: Yes | W127: 36000 | AA127: =IF(COUNT(X127,Y127,Z127)=0,"",SUM(X127,Y127,Z127)) | AB127: =IFERROR(IF(OR(W127="",AA127=""),"",(W127-AA127)/W127),"") | AC127: =IFERROR(IF(OR(AA127="",AA127=0),"",W127/AA127),"") | AD127: Active | AE127: No | AL127: No
A128: DSGN-EARRNG2-VISHAB | B128: Vishab Earrings (2 pcs) | D128: earrings 2 pcs. | E128: Vishab | G128: 4 | H128: Vishap (dragon-stone) motif | I128: Vishaps are ancient Armenian dragon-stones (vishapakar) found in the highlands, among the oldest carved monuments in the region. | L128: 925 Silver Gold-Plated | M128: 24k Gold Plate | N128: Hot / Vitreous | U128: Yes | W128: 36000 | AA128: =IF(COUNT(X128,Y128,Z128)=0,"",SUM(X128,Y128,Z128)) | AB128: =IFERROR(IF(OR(W128="",AA128=""),"",(W128-AA128)/W128),"") | AC128: =IFERROR(IF(OR(AA128="",AA128=0),"",W128/AA128),"") | AD128: Active | AE128: No | AL128: No
... A165: DSGN-CHBRAC-VISHABAREVAGORG | B165: Արեւագորգի Վիշապ | D165: chain bracelet | E165: Vishab Arevagorg | G165: 5 | H165: Vishap + Arevagorg (sun-carpet) motif | I165: Combines the vishap (dragon) motif with the arevagorg (sun-carpet) — an Armenian solar ornament symbolising life and eternity. | L165: 925 Silver Gold-Plated | M165: 24k Gold Plate | N165: Hot / Vitreous | U165: Yes | W165: 17000 | AA165: =IF(COUNT(X165,Y165,Z165)=0,"",SUM(X165,Y165,Z165)) | AB165: =IFERROR(IF(OR(W165="",AA165=""),"",(W165-AA165)/W165),"") | AC165: =IFERROR(IF(OR(AA165="",AA165=0),"",W165/AA165),"") | AD165: Active | AE165: No | AL165: No

Sheet Variants
A1: PRODUCT | I1: PRICING | O1: INVENTORY | T1: COMPLIANCE / PHYSICAL | Z1: CHANNELS | AD1: PERFORMANCE
A2: ID (SKU) | B2: DesignID | C2: Design name | D2: Category | E2: Collection | F2: Subcollection (letter) | G2: Size | H2: Color | I2: Price (AMD) | J2: Price (USD) | K2: Price (EUR) | L2: Price (RUB) | M2: Cost (AMD) | N2: Margin % | O2: Stock on hand | P2: Reserved | Q2: Available | R2: Reorder point | S2: Reorder flag | T2: Location / Bin | U2: Barcode / GTIN | V2: HS code | W2: Country of origin | X2: Weight (g) | Y2: Variant image URL | Z2: On website? | AA2: On Etsy? | AB2: On IG? | AC2: In stockists? | AD2: Status | AE2: Units sold | AF2: Revenue (AMD) | AG2: Last sold | AH2: Notes
A3: KARNI-PEND-ALPHA-AYB-RED | B3: DSGN-PEND-ALPHA-AYB | C3: Bird Letter Pendant | D3: Pendant | E3: Alphabet | F3: Ա | H3: red | I3: 19000 | J3: =IF($I3="","",ROUND($I3*Dropdowns!$K$5,2)) -> 49.4 | K3: =IF($I3="","",ROUND($I3*Dropdowns!$K$6,2)) -> 45.6 | L3: =IF($I3="","",ROUND($I3*Dropdowns!$K$7,2)) -> 3895 | M3: =IFERROR(IF($B3="","",VLOOKUP($B3,Designs!$A$3:$AP$165,27,FALSE())),"") | N3: =IFERROR(IF(OR($I3="",$M3="",$M3=0),"",($I3-$M3)/$I3),"") | O3: 0 | P3: 0 | Q3: =IF($O3="","",$O3-IF($P3="",0,$P3)) -> 0 | R3: 2 | S3: =IF($O3="","",IF($Q3<=$R3,"⚠ REORDER","OK")) -> ⚠ REORDER | V3: 7117.19 | W3: Armenia | Z3: No | AA3: No | AB3: No | AC3: No | AD3: Active | AE3: =IFERROR(SUMIFS(Transactions!$F:$F,Transactions!$C:$C,$A3,Transactions!$D:$D,"Sale"),0) -> 1 | AF3: =IFERROR(SUMIFS(Transactions!$H:$H,Transactions!$C:$C,$A3,Transactions!$D:$D,"Sale"),0) -> 19000 | AG3: =IFERROR(IF(maxifs(Transactions!$B:$B,Transactions!$C:$C,$A3,Transactions!$D:$D,"Sale")=0,"",maxifs(Transactions!$B:$B,Transactions!$C:$C,$A3,Transactions!$D:$D,"Sale")),"")
A4: KARNI-PEND-ALPHA-AYB-TURQUOISE | B4: DSGN-PEND-ALPHA-AYB | C4: Bird Letter Pendant | D4: Pendant | E4: Alphabet | F4: Ա | H4: turquoise | I4: 19000 | J4: =IF($I4="","",ROUND($I4*Dropdowns!$K$5,2)) -> 49.4 | K4: =IF($I4="","",ROUND($I4*Dropdowns!$K$6,2)) -> 45.6 | L4: =IF($I4="","",ROUND($I4*Dropdowns!$K$7,2)) -> 3895 | M4: =IFERROR(IF($B4="","",VLOOKUP($B4,Designs!$A$3:$AP$165,27,FALSE())),"") | N4: =IFERROR(IF(OR($I4="",$M4="",$M4=0),"",($I4-$M4)/$I4),"") | O4: 0 | P4: 0 | Q4: =IF($O4="","",$O4-IF($P4="",0,$P4)) -> 0 | R4: 2 | S4: =IF($O4="","",IF($Q4<=$R4,"⚠ REORDER","OK")) -> ⚠ REORDER | V4: 7117.19 | W4: Armenia | Z4: No | AA4: No | AB4: No | AC4: No | AD4: Active | AE4: =IFERROR(SUMIFS(Transactions!$F:$F,Transactions!$C:$C,$A4,Transactions!$D:$D,"Sale"),0) -> 0 | AF4: =IFERROR(SUMIFS(Transactions!$H:$H,Transactions!$C:$C,$A4,Transactions!$D:$D,"Sale"),0) -> 0 | AG4: =IFERROR(IF(maxifs(Transactions!$B:$B,Transactions!$C:$C,$A4,Transactions!$D:$D,"Sale")=0,"",maxifs(Transactions!$B:$B,Transactions!$C:$C,$A4,Transactions!$D:$D,"Sale")),"")
A5: KARNI-PEND-ALPHA-AYB-WHITE | B5: DSGN-PEND-ALPHA-AYB | C5: Bird Letter Pendant | D5: Pendant | E5: Alphabet | F5: Ա | H5: white | I5: 19000 | J5: =IF($I5="","",ROUND($I5*Dropdowns!$K$5,2)) -> 49.4 | K5: =IF($I5="","",ROUND($I5*Dropdowns!$K$6,2)) -> 45.6 | L5: =IF($I5="","",ROUND($I5*Dropdowns!$K$7,2)) -> 3895 | M5: =IFERROR(IF($B5="","",VLOOKUP($B5,Designs!$A$3:$AP$165,27,FALSE())),"") | N5: =IFERROR(IF(OR($I5="",$M5="",$M5=0),"",($I5-$M5)/$I5),"") | O5: 0 | P5: 0 | Q5: =IF($O5="","",$O5-IF($P5="",0,$P5)) -> 0 | R5: 2 | S5: =IF($O5="","",IF($Q5<=$R5,"⚠ REORDER","OK")) -> ⚠ REORDER | V5: 7117.19 | W5: Armenia | Z5: No | AA5: No | AB5: No | AC5: No | AD5: Active | AE5: =IFERROR(SUMIFS(Transactions!$F:$F,Transactions!$C:$C,$A5,Transactions!$D:$D,"Sale"),0) -> 0 | AF5: =IFERROR(SUMIFS(Transactions!$H:$H,Transactions!$C:$C,$A5,Transactions!$D:$D,"Sale"),0) -> 0 | AG5: =IFERROR(IF(maxifs(Transactions!$B:$B,Transactions!$C:$C,$A5,Transactions!$D:$D,"Sale")=0,"",maxifs(Transactions!$B:$B,Transactions!$C:$C,$A5,Transactions!$D:$D,"Sale")),"")
A6: KARNI-PEND-ALPHA-BEN-RED | B6: DSGN-PEND-ALPHA-BEN | C6: Bird Letter Pendant | D6: Pendant | E6: Alphabet | F6: Բ | H6: red | I6: 19000 | J6: =IF($I6="","",ROUND($I6*Dropdowns!$K$5,2)) -> 49.4 | K6: =IF($I6="","",ROUND($I6*Dropdowns!$K$6,2)) -> 45.6 | L6: =IF($I6="","",ROUND($I6*Dropdowns!$K$7,2)) -> 3895 | M6: =IFERROR(IF($B6="","",VLOOKUP($B6,Designs!$A$3:$AP$165,27,FALSE())),"") | N6: =IFERROR(IF(OR($I6="",$M6="",$M6=0),"",($I6-$M6)/$I6),"") | O6: 0 | P6: 0 | Q6: =IF($O6="","",$O6-IF($P6="",0,$P6)) -> 0 | R6: 2 | S6: =IF($O6="","",IF($Q6<=$R6,"⚠ REORDER","OK")) -> ⚠ REORDER | V6: 7117.19 | W6: Armenia | Z6: No | AA6: No | AB6: No | AC6: No | AD6: Active | AE6: =IFERROR(SUMIFS(Transactions!$F:$F,Transactions!$C:$C,$A6,Transactions!$D:$D,"Sale"),0) -> 0 | AF6: =IFERROR(SUMIFS(Transactions!$H:$H,Transactions!$C:$C,$A6,Transactions!$D:$D,"Sale"),0) -> 0 | AG6: =IFERROR(IF(maxifs(Transactions!$B:$B,Transactions!$C:$C,$A6,Transactions!$D:$D,"Sale")=0,"",maxifs(Transactions!$B:$B,Transactions!$C:$C,$A6,Transactions!$D:$D,"Sale")),"")
A7: KARNI-PEND-ALPHA-BEN-TURQUOISE | B7: DSGN-PEND-ALPHA-BEN | C7: Bird Letter Pendant | D7: Pendant | E7: Alphabet | F7: Բ | H7: turquoise | I7: 19000 | J7: =IF($I7="","",ROUND($I7*Dropdowns!$K$5,2)) -> 49.4 | K7: =IF($I7="","",ROUND($I7*Dropdowns!$K$6,2)) -> 45.6 | L7: =IF($I7="","",ROUND($I7*Dropdowns!$K$7,2)) -> 3895 | M7: =IFERROR(IF($B7="","",VLOOKUP($B7,Designs!$A$3:$AP$165,27,FALSE())),"") | N7: =IFERROR(IF(OR($I7="",$M7="",$M7=0),"",($I7-$M7)/$I7),"") | O7: 0 | P7: 0 | Q7: =IF($O7="","",$O7-IF($P7="",0,$P7)) -> 0 | R7: 2 | S7: =IF($O7="","",IF($Q7<=$R7,"⚠ REORDER","OK")) -> ⚠ REORDER | V7: 7117.19 | W7: Armenia | Z7: No | AA7: No | AB7: No | AC7: No | AD7: Active | AE7: =IFERROR(SUMIFS(Transactions!$F:$F,Transactions!$C:$C,$A7,Transactions!$D:$D,"Sale"),0) -> 0 | AF7: =IFERROR(SUMIFS(Transactions!$H:$H,Transactions!$C:$C,$A7,Transactions!$D:$D,"Sale"),0) -> 0 | AG7: =IFERROR(IF(maxifs(Transactions!$B:$B,Transactions!$C:$C,$A7,Transactions!$D:$D,"Sale")=0,"",maxifs(Transactions!$B:$B,Transactions!$C:$C,$A7,Transactions!$D:$D,"Sale")),"")
A8: KARNI-PEND-ALPHA-BEN-WHITE | B8: DSGN-PEND-ALPHA-BEN | C8: Bird Letter Pendant | D8: Pendant | E8: Alphabet | F8: Բ | H8: white | I8: 19000 | J8: =IF($I8="","",ROUND($I8*Dropdowns!$K$5,2)) -> 49.4 | K8: =IF($I8="","",ROUND($I8*Dropdowns!$K$6,2)) -> 45.6 | L8: =IF($I8="","",ROUND($I8*Dropdowns!$K$7,2)) -> 3895 | M8: =IFERROR(IF($B8="","",VLOOKUP($B8,Designs!$A$3:$AP$165,27,FALSE())),"") | N8: =IFERROR(IF(OR($I8="",$M8="",$M8=0),"",($I8-$M8)/$I8),"") | O8: 0 | P8: 0 | Q8: =IF($O8="","",$O8-IF($P8="",0,$P8)) -> 0 | R8: 2 | S8: =IF($O8="","",IF($Q8<=$R8,"⚠ REORDER","OK")) -> ⚠ REORDER | V8: 7117.19 | W8: Armenia | Z8: No | AA8: No | AB8: No | AC8: No | AD8: Active | AE8: =IFERROR(SUMIFS(Transactions!$F:$F,Transactions!$C:$C,$A8,Transactions!$D:$D,"Sale"),0) -> 0 | AF8: =IFERROR(SUMIFS(Transactions!$H:$H,Transactions!$C:$C,$A8,Transactions!$D:$D,"Sale"),0) -> 0 | AG8: =IFERROR(IF(maxifs(Transactions!$B:$B,Transactions!$C:$C,$A8,Transactions!$D:$D,"Sale")=0,"",maxifs(Transactions!$B:$B,Transactions!$C:$C,$A8,Transactions!$D:$D,"Sale")),"")
A9: KARNI-PEND-ALPHA-GIM-RED | B9: DSGN-PEND-ALPHA-GIM | C9: Bird Letter Pendant | D9: Pendant | E9: Alphabet | F9: Գ | H9: red | I9: 19000 | J9: =IF($I9="","",ROUND($I9*Dropdowns!$K$5,2)) -> 49.4 | K9: =IF($I9="","",ROUND($I9*Dropdowns!$K$6,2)) -> 45.6 | L9: =IF($I9="","",ROUND($I9*Dropdowns!$K$7,2)) -> 3895 | M9: =IFERROR(IF($B9="","",VLOOKUP($B9,Designs!$A$3:$AP$165,27,FALSE())),"") | N9: =IFERROR(IF(OR($I9="",$M9="",$M9=0),"",($I9-$M9)/$I9),"") | O9: 0 | P9: 0 | Q9: =IF($O9="","",$O9-IF($P9="",0,$P9)) -> 0 | R9: 2 | S9: =IF($O9="","",IF($Q9<=$R9,"⚠ REORDER","OK")) -> ⚠ REORDER | V9: 7117.19 | W9: Armenia | Z9: No | AA9: No | AB9: No | AC9: No | AD9: Active | AE9: =IFERROR(SUMIFS(Transactions!$F:$F,Transactions!$C:$C,$A9,Transactions!$D:$D,"Sale"),0) -> 0 | AF9: =IFERROR(SUMIFS(Transactions!$H:$H,Transactions!$C:$C,$A9,Transactions!$D:$D,"Sale"),0) -> 0 | AG9: =IFERROR(IF(maxifs(Transactions!$B:$B,Transactions!$C:$C,$A9,Transactions!$D:$D,"Sale")=0,"",maxifs(Transactions!$B:$B,Transactions!$C:$C,$A9,Transactions!$D:$D,"Sale")),"")
A10: KARNI-PEND-ALPHA-GIM-TURQUOISE | B10: DSGN-PEND-ALPHA-GIM | C10: Bird Letter Pendant | D10: Pendant | E10: Alphabet | F10: Գ | H10: turquoise | I10: 19000 | J10: =IF($I10="","",ROUND($I10*Dropdowns!$K$5,2)) -> 49.4 | K10: =IF($I10="","",ROUND($I10*Dropdowns!$K$6,2)) -> 45.6 | L10: =IF($I10="","",ROUND($I10*Dropdowns!$K$7,2)) -> 3895 | M10: =IFERROR(IF($B10="","",VLOOKUP($B10,Designs!$A$3:$AP$165,27,FALSE())),"") | N10: =IFERROR(IF(OR($I10="",$M10="",$M10=0),"",($I10-$M10)/$I10),"") | O10: 0 | P10: 0 | Q10: =IF($O10="","",$O10-IF($P10="",0,$P10)) -> 0 | R10: 2 | S10: =IF($O10="","",IF($Q10<=$R10,"⚠ REORDER","OK")) -> ⚠ REORDER | V10: 7117.19 | W10: Armenia | Z10: No | AA10: No | AB10: No | AC10: No | AD10: Active | AE10: =IFERROR(SUMIFS(Transactions!$F:$F,Transactions!$C:$C,$A10,Transactions!$D:$D,"Sale"),0) -> 0 | AF10: =IFERROR(SUMIFS(Transactions!$H:$H,Transactions!$C:$C,$A10,Transactions!$D:$D,"Sale"),0) -> 0 | AG10: =IFERROR(IF(maxifs(Transactions!$B:$B,Transactions!$C:$C,$A10,Transactions!$D:$D,"Sale")=0,"",maxifs(Transactions!$B:$B,Transactions!$C:$C,$A10,Transactions!$D:$D,"Sale")),"")
A11: KARNI-PEND-ALPHA-GIM-WHITE | B11: DSGN-PEND-ALPHA-GIM | C11: Bird Letter Pendant | D11: Pendant | E11: Alphabet | F11: Գ | H11: white | I11: 19000 | J11: =IF($I11="","",ROUND($I11*Dropdowns!$K$5,2)) -> 49.4 | K11: =IF($I11="","",ROUND($I11*Dropdowns!$K$6,2)) -> 45.6 | L11: =IF($I11="","",ROUND($I11*Dropdowns!$K$7,2)) -> 3895 | M11: =IFERROR(IF($B11="","",VLOOKUP($B11,Designs!$A$3:$AP$165,27,FALSE())),"") | N11: =IFERROR(IF(OR($I11="",$M11="",$M11=0),"",($I11-$M11)/$I11),"") | O11: 0 | P11: 0 | Q11: =IF($O11="","",$O11-IF($P11="",0,$P11)) -> 0 | R11: 2 | S11: =IF($O11="","",IF($Q11<=$R11,"⚠ REORDER","OK")) -> ⚠ REORDER | V11: 7117.19 | W11: Armenia | Z11: No | AA11: No | AB11: No | AC11: No | AD11: Active | AE11: =IFERROR(SUMIFS(Transactions!$F:$F,Transactions!$C:$C,$A11,Transactions!$D:$D,"Sale"),0) -> 0 | AF11: =IFERROR(SUMIFS(Transactions!$H:$H,Transactions!$C:$C,$A11,Transactions!$D:$D,"Sale"),0) -> 0 | AG11: =IFERROR(IF(maxifs(Transactions!$B:$B,Transactions!$C:$C,$A11,Transactions!$D:$D,"Sale")=0,"",maxifs(Transactions!$B:$B,Transactions!$C:$C,$A11,Transactions!$D:$D,"Sale")),"")
A12: KARNI-PEND-ALPHA-DA-RED | B12: DSGN-PEND-ALPHA-DA | C12: Bird Letter Pendant | D12: Pendant | E12: Alphabet | F12: Դ | H12: red | I12: 19000 | J12: =IF($I12="","",ROUND($I12*Dropdowns!$K$5,2)) -> 49.4 | K12: =IF($I12="","",ROUND($I12*Dropdowns!$K$6,2)) -> 45.6 | L12: =IF($I12="","",ROUND($I12*Dropdowns!$K$7,2)) -> 3895 | M12: =IFERROR(IF($B12="","",VLOOKUP($B12,Designs!$A$3:$AP$165,27,FALSE())),"") | N12: =IFERROR(IF(OR($I12="",$M12="",$M12=0),"",($I12-$M12)/$I12),"") | O12: 0 | P12: 0 | Q12: =IF($O12="","",$O12-IF($P12="",0,$P12)) -> 0 | R12: 2 | S12: =IF($O12="","",IF($Q12<=$R12,"⚠ REORDER","OK")) -> ⚠ REORDER | V12: 7117.19 | W12: Armenia | Z12: No | AA12: No | AB12: No | AC12: No | AD12: Active | AE12: =IFERROR(SUMIFS(Transactions!$F:$F,Transactions!$C:$C,$A12,Transactions!$D:$D,"Sale"),0) -> 0 | AF12: =IFERROR(SUMIFS(Transactions!$H:$H,Transactions!$C:$C,$A12,Transactions!$D:$D,"Sale"),0) -> 0 | AG12: =IFERROR(IF(maxifs(Transactions!$B:$B,Transactions!$C:$C,$A12,Transactions!$D:$D,"Sale")=0,"",maxifs(Transactions!$B:$B,Transactions!$C:$C,$A12,Transactions!$D:$D,"Sale")),"")
A13: KARNI-PEND-ALPHA-DA-TURQUOISE | B13: DSGN-PEND-ALPHA-DA | C13: Bird Letter Pendant | D13: Pendant | E13: Alphabet | F13: Դ | H13: turquoise | I13: 19000 | J13: =IF($I13="","",ROUND($I13*Dropdowns!$K$5,2)) -> 49.4 | K13: =IF($I13="","",ROUND($I13*Dropdowns!$K$6,2)) -> 45.6 | L13: =IF($I13="","",ROUND($I13*Dropdowns!$K$7,2)) -> 3895 | M13: =IFERROR(IF($B13="","",VLOOKUP($B13,Designs!$A$3:$AP$165,27,FALSE())),"") | N13: =IFERROR(IF(OR($I13="",$M13="",$M13=0),"",($I13-$M13)/$I13),"") | O13: 0 | P13: 0 | Q13: =IF($O13="","",$O13-IF($P13="",0,$P13)) -> 0 | R13: 2 | S13: =IF($O13="","",IF($Q13<=$R13,"⚠ REORDER","OK")) -> ⚠ REORDER | V13: 7117.19 | W13: Armenia | Z13: No | AA13: No | AB13: No | AC13: No | AD13: Active | AE13: =IFERROR(SUMIFS(Transactions!$F:$F,Transactions!$C:$C,$A13,Transactions!$D:$D,"Sale"),0) -> 0 | AF13: =IFERROR(SUMIFS(Transactions!$H:$H,Transactions!$C:$C,$A13,Transactions!$D:$D,"Sale"),0) -> 0 | AG13: =IFERROR(IF(maxifs(Transactions!$B:$B,Transactions!$C:$C,$A13,Transactions!$D:$D,"Sale")=0,"",maxifs(Transactions!$B:$B,Transactions!$C:$C,$A13,Transactions!$D:$D,"Sale")),"")
A14: KARNI-PEND-ALPHA-DA-WHITE | B14: DSGN-PEND-ALPHA-DA | C14: Bird Letter Pendant | D14: Pendant | E14: Alphabet | F14: Դ | H14: white | I14: 19000 | J14: =IF($I14="","",ROUND($I14*Dropdowns!$K$5,2)) -> 49.4 | K14: =IF($I14="","",ROUND($I14*Dropdowns!$K$6,2)) -> 45.6 | L14: =IF($I14="","",ROUND($I14*Dropdowns!$K$7,2)) -> 3895 | M14: =IFERROR(IF($B14="","",VLOOKUP($B14,Designs!$A$3:$AP$165,27,FALSE())),"") | N14: =IFERROR(IF(OR($I14="",$M14="",$M14=0),"",($I14-$M14)/$I14),"") | O14: 0 | P14: 0 | Q14: =IF($O14="","",$O14-IF($P14="",0,$P14)) -> 0 | R14: 2 | S14: =IF($O14="","",IF($Q14<=$R14,"⚠ REORDER","OK")) -> ⚠ REORDER | V14: 7117.19 | W14: Armenia | Z14: No | AA14: No | AB14: No | AC14: No | AD14: Active | AE14: =IFERROR(SUMIFS(Transactions!$F:$F,Transactions!$C:$C,$A14,Transactions!$D:$D,"Sale"),0) -> 0 | AF14: =IFERROR(SUMIFS(Transactions!$H:$H,Transactions!$C:$C,$A14,Transactions!$D:$D,"Sale"),0) -> 0 | AG14: =IFERROR(IF(maxifs(Transactions!$B:$B,Transactions!$C:$C,$A14,Transactions!$D:$D,"Sale")=0,"",maxifs(Transactions!$B:$B,Transactions!$C:$C,$A14,Transactions!$D:$D,"Sale")),"")
... A268: KARNI-BRCH-ALPHA-FEH-TURQUOISE | B268: DSGN-BRCH-ALPHA-FEH | C268: Bird Letter Brooch | D268: Brooch | E268: Alphabet | F268: Ֆ | H268: turquoise | I268: 25000 | J268: =IF($I268="","",ROUND($I268*Dropdowns!$K$5,2)) -> 65 | K268: =IF($I268="","",ROUND($I268*Dropdowns!$K$6,2)) -> 60 | L268: =IF($I268="","",ROUND($I268*Dropdowns!$K$7,2)) -> 5125 | M268: =IFERROR(IF($B268="","",VLOOKUP($B268,Designs!$A$3:$AP$165,27,FALSE())),"") | N268: =IFERROR(IF(OR($I268="",$M268="",$M268=0),"",($I268-$M268)/$I268),"") | O268: 0 | P268: 0 | Q268: =IF($O268="","",$O268-IF($P268="",0,$P268)) -> 0 | R268: 2 | S268: =IF($O268="","",IF($Q268<=$R268,"⚠ REORDER","OK")) -> ⚠ REORDER | V268: 7117.19 | W268: Armenia | Z268: No | AA268: No | AB268: No | AC268: No | AD268: Active | AE268: =IFERROR(SUMIFS(Transactions!$F:$F,Transactions!$C:$C,$A268,Transactions!$D:$D,"Sale"),0) -> 0 | AF268: =IFERROR(SUMIFS(Transactions!$H:$H,Transactions!$C:$C,$A268,Transactions!$D:$D,"Sale"),0) -> 0 | AG268: =IFERROR(IF(maxifs(Transactions!$B:$B,Transactions!$C:$C,$A268,Transactions!$D:$D,"Sale")=0,"",maxifs(Transactions!$B:$B,Transactions!$C:$C,$A268,Transactions!$D:$D,"Sale")),"")
A269: KARNI-EARRNG-MARASH-S-BLUE | B269: DSGN-EARRNG-MARASH-S | C269: Marash Earrings | D269: Earring | E269: Marash | G269: small | H269: blue | I269: 13000 | J269: =IF($I269="","",ROUND($I269*Dropdowns!$K$5,2)) -> 33.8 | K269: =IF($I269="","",ROUND($I269*Dropdowns!$K$6,2)) -> 31.2 | L269: =IF($I269="","",ROUND($I269*Dropdowns!$K$7,2)) -> 2665 | M269: =IFERROR(IF($B269="","",VLOOKUP($B269,Designs!$A$3:$AP$165,27,FALSE())),"") | N269: =IFERROR(IF(OR($I269="",$M269="",$M269=0),"",($I269-$M269)/$I269),"") | O269: 0 | P269: 0 | Q269: =IF($O269="","",$O269-IF($P269="",0,$P269)) -> 0 | R269: 2 | S269: =IF($O269="","",IF($Q269<=$R269,"⚠ REORDER","OK")) -> ⚠ REORDER | V269: 7117.19 | W269: Armenia | Z269: No | AA269: No | AB269: No | AC269: No | AD269: Active | AE269: =IFERROR(SUMIFS(Transactions!$F:$F,Transactions!$C:$C,$A269,Transactions!$D:$D,"Sale"),0) -> 0 | AF269: =IFERROR(SUMIFS(Transactions!$H:$H,Transactions!$C:$C,$A269,Transactions!$D:$D,"Sale"),0) -> 0 | AG269: =IFERROR(IF(maxifs(Transactions!$B:$B,Transactions!$C:$C,$A269,Transactions!$D:$D,"Sale")=0,"",maxifs(Transactions!$B:$B,Transactions!$C:$C,$A269,Transactions!$D:$D,"Sale")),"")
A270: KARNI-EARRNG-MARASH-S-WHITE | B270: DSGN-EARRNG-MARASH-S | C270: Marash Earrings | D270: Earring | E270: Marash | G270: small | H270: white | I270: 13000 | J270: =IF($I270="","",ROUND($I270*Dropdowns!$K$5,2)) -> 33.8 | K270: =IF($I270="","",ROUND($I270*Dropdowns!$K$6,2)) -> 31.2 | L270: =IF($I270="","",ROUND($I270*Dropdowns!$K$7,2)) -> 2665 | M270: =IFERROR(IF($B270="","",VLOOKUP($B270,Designs!$A$3:$AP$165,27,FALSE())),"") | N270: =IFERROR(IF(OR($I270="",$M270="",$M270=0),"",($I270-$M270)/$I270),"") | O270: 0 | P270: 0 | Q270: =IF($O270="","",$O270-IF($P270="",0,$P270)) -> 0 | R270: 2 | S270: =IF($O270="","",IF($Q270<=$R270,"⚠ REORDER","OK")) -> ⚠ REORDER | V270: 7117.19 | W270: Armenia | Z270: No | AA270: No | AB270: No | AC270: No | AD270: Active | AE270: =IFERROR(SUMIFS(Transactions!$F:$F,Transactions!$C:$C,$A270,Transactions!$D:$D,"Sale"),0) -> 0 | AF270: =IFERROR(SUMIFS(Transactions!$H:$H,Transactions!$C:$C,$A270,Transactions!$D:$D,"Sale"),0) -> 0 | AG270: =IFERROR(IF(maxifs(Transactions!$B:$B,Transactions!$C:$C,$A270,Transactions!$D:$D,"Sale")=0,"",maxifs(Transactions!$B:$B,Transactions!$C:$C,$A270,Transactions!$D:$D,"Sale")),"")
A271: KARNI-EARRNG-MARASH-S-BORDEAUX | B271: DSGN-EARRNG-MARASH-S | C271: Marash Earrings | D271: Earring | E271: Marash | G271: small | H271: bordeaux | I271: 13000 | J271: =IF($I271="","",ROUND($I271*Dropdowns!$K$5,2)) -> 33.8 | K271: =IF($I271="","",ROUND($I271*Dropdowns!$K$6,2)) -> 31.2 | L271: =IF($I271="","",ROUND($I271*Dropdowns!$K$7,2)) -> 2665 | M271: =IFERROR(IF($B271="","",VLOOKUP($B271,Designs!$A$3:$AP$165,27,FALSE())),"") | N271: =IFERROR(IF(OR($I271="",$M271="",$M271=0),"",($I271-$M271)/$I271),"") | O271: 0 | P271: 0 | Q271: =IF($O271="","",$O271-IF($P271="",0,$P271)) -> 0 | R271: 2 | S271: =IF($O271="","",IF($Q271<=$R271,"⚠ REORDER","OK")) -> ⚠ REORDER | V271: 7117.19 | W271: Armenia | Z271: No | AA271: No | AB271: No | AC271: No | AD271: Active | AE271: =IFERROR(SUMIFS(Transactions!$F:$F,Transactions!$C:$C,$A271,Transactions!$D:$D,"Sale"),0) -> 0 | AF271: =IFERROR(SUMIFS(Transactions!$H:$H,Transactions!$C:$C,$A271,Transactions!$D:$D,"Sale"),0) -> 0 | AG271: =IFERROR(IF(maxifs(Transactions!$B:$B,Transactions!$C:$C,$A271,Transactions!$D:$D,"Sale")=0,"",maxifs(Transactions!$B:$B,Transactions!$C:$C,$A271,Transactions!$D:$D,"Sale")),"")
A272: KARNI-EARRNG-MARASH-S-TURQUOISE | B272: DSGN-EARRNG-MARASH-S | C272: Marash Earrings | D272: Earring | E272: Marash | G272: small | H272: turquoise | I272: 13000 | J272: =IF($I272="","",ROUND($I272*Dropdowns!$K$5,2)) -> 33.8 | K272: =IF($I272="","",ROUND($I272*Dropdowns!$K$6,2)) -> 31.2 | L272: =IF($I272="","",ROUND($I272*Dropdowns!$K$7,2)) -> 2665 | M272: =IFERROR(IF($B272="","",VLOOKUP($B272,Designs!$A$3:$AP$165,27,FALSE())),"") | N272: =IFERROR(IF(OR($I272="",$M272="",$M272=0),"",($I272-$M272)/$I272),"") | O272: 0 | P272: 0 | Q272: =IF($O272="","",$O272-IF($P272="",0,$P272)) -> 0 | R272: 2 | S272: =IF($O272="","",IF($Q272<=$R272,"⚠ REORDER","OK")) -> ⚠ REORDER | V272: 7117.19 | W272: Armenia | Z272: No | AA272: No | AB272: No | AC272: No | AD272: Active | AE272: =IFERROR(SUMIFS(Transactions!$F:$F,Transactions!$C:$C,$A272,Transactions!$D:$D,"Sale"),0) -> 0 | AF272: =IFERROR(SUMIFS(Transactions!$H:$H,Transactions!$C:$C,$A272,Transactions!$D:$D,"Sale"),0) -> 0 | AG272: =IFERROR(IF(maxifs(Transactions!$B:$B,Transactions!$C:$C,$A272,Transactions!$D:$D,"Sale")=0,"",maxifs(Transactions!$B:$B,Transactions!$C:$C,$A272,Transactions!$D:$D,"Sale")),"")
A273: KARNI-EARRNG-MARASH-S-GREEN | B273: DSGN-EARRNG-MARASH-S | C273: Marash Earrings | D273: Earring | E273: Marash | G273: small | H273: green | I273: 13000 | J273: =IF($I273="","",ROUND($I273*Dropdowns!$K$5,2)) -> 33.8 | K273: =IF($I273="","",ROUND($I273*Dropdowns!$K$6,2)) -> 31.2 | L273: =IF($I273="","",ROUND($I273*Dropdowns!$K$7,2)) -> 2665 | M273: =IFERROR(IF($B273="","",VLOOKUP($B273,Designs!$A$3:$AP$165,27,FALSE())),"") | N273: =IFERROR(IF(OR($I273="",$M273="",$M273=0),"",($I273-$M273)/$I273),"") | O273: 0 | P273: 0 | Q273: =IF($O273="","",$O273-IF($P273="",0,$P273)) -> 0 | R273: 2 | S273: =IF($O273="","",IF($Q273<=$R273,"⚠ REORDER","OK")) -> ⚠ REORDER | V273: 7117.19 | W273: Armenia | Z273: No | AA273: No | AB273: No | AC273: No | AD273: Active | AE273: =IFERROR(SUMIFS(Transactions!$F:$F,Transactions!$C:$C,$A273,Transactions!$D:$D,"Sale"),0) -> 0 | AF273: =IFERROR(SUMIFS(Transactions!$H:$H,Transactions!$C:$C,$A273,Transactions!$D:$D,"Sale"),0) -> 0 | AG273: =IFERROR(IF(maxifs(Transactions!$B:$B,Transactions!$C:$C,$A273,Transactions!$D:$D,"Sale")=0,"",maxifs(Transactions!$B:$B,Transactions!$C:$C,$A273,Transactions!$D:$D,"Sale")),"")
A274: KARNI-EARRNG-MARASH-M-BLUE-WHITE | B274: DSGN-EARRNG-MARASH-M | C274: Marash Earrings | D274: Earring | E274: Marash | G274: medium | H274: blue-white | I274: 27000 | J274: =IF($I274="","",ROUND($I274*Dropdowns!$K$5,2)) -> 70.2 | K274: =IF($I274="","",ROUND($I274*Dropdowns!$K$6,2)) -> 64.8 | L274: =IF($I274="","",ROUND($I274*Dropdowns!$K$7,2)) -> 5535 | M274: =IFERROR(IF($B274="","",VLOOKUP($B274,Designs!$A$3:$AP$165,27,FALSE())),"") | N274: =IFERROR(IF(OR($I274="",$M274="",$M274=0),"",($I274-$M274)/$I274),"") | O274: 0 | P274: 0 | Q274: =IF($O274="","",$O274-IF($P274="",0,$P274)) -> 0 | R274: 2 | S274: =IF($O274="","",IF($Q274<=$R274,"⚠ REORDER","OK")) -> ⚠ REORDER | V274: 7117.19 | W274: Armenia | Z274: No | AA274: No | AB274: No | AC274: No | AD274: Active | AE274: =IFERROR(SUMIFS(Transactions!$F:$F,Transactions!$C:$C,$A274,Transactions!$D:$D,"Sale"),0) -> 0 | AF274: =IFERROR(SUMIFS(Transactions!$H:$H,Transactions!$C:$C,$A274,Transactions!$D:$D,"Sale"),0) -> 0 | AG274: =IFERROR(IF(maxifs(Transactions!$B:$B,Transactions!$C:$C,$A274,Transactions!$D:$D,"Sale")=0,"",maxifs(Transactions!$B:$B,Transactions!$C:$C,$A274,Transactions!$D:$D,"Sale")),"")
A275: KARNI-EARRNG-MARASH-M-WHITE-BLUE | B275: DSGN-EARRNG-MARASH-M | C275: Marash Earrings | D275: Earring | E275: Marash | G275: medium | H275: white-blue | I275: 27000 | J275: =IF($I275="","",ROUND($I275*Dropdowns!$K$5,2)) -> 70.2 | K275: =IF($I275="","",ROUND($I275*Dropdowns!$K$6,2)) -> 64.8 | L275: =IF($I275="","",ROUND($I275*Dropdowns!$K$7,2)) -> 5535 | M275: =IFERROR(IF($B275="","",VLOOKUP($B275,Designs!$A$3:$AP$165,27,FALSE())),"") | N275: =IFERROR(IF(OR($I275="",$M275="",$M275=0),"",($I275-$M275)/$I275),"") | O275: 0 | P275: 0 | Q275: =IF($O275="","",$O275-IF($P275="",0,$P275)) -> 0 | R275: 2 | S275: =IF($O275="","",IF($Q275<=$R275,"⚠ REORDER","OK")) -> ⚠ REORDER | V275: 7117.19 | W275: Armenia | Z275: No | AA275: No | AB275: No | AC275: No | AD275: Active | AE275: =IFERROR(SUMIFS(Transactions!$F:$F,Transactions!$C:$C,$A275,Transactions!$D:$D,"Sale"),0) -> 0 | AF275: =IFERROR(SUMIFS(Transactions!$H:$H,Transactions!$C:$C,$A275,Transactions!$D:$D,"Sale"),0) -> 0 | AG275: =IFERROR(IF(maxifs(Transactions!$B:$B,Transactions!$C:$C,$A275,Transactions!$D:$D,"Sale")=0,"",maxifs(Transactions!$B:$B,Transactions!$C:$C,$A275,Transactions!$D:$D,"Sale")),"")
A276: KARNI-EARRNG-MARASH-M-WHITE-BORDEAUX | B276: DSGN-EARRNG-MARASH-M | C276: Marash Earrings | D276: Earring | E276: Marash | G276: medium | H276: white-bordeaux | I276: 27000 | J276: =IF($I276="","",ROUND($I276*Dropdowns!$K$5,2)) -> 70.2 | K276: =IF($I276="","",ROUND($I276*Dropdowns!$K$6,2)) -> 64.8 | L276: =IF($I276="","",ROUND($I276*Dropdowns!$K$7,2)) -> 5535 | M276: =IFERROR(IF($B276="","",VLOOKUP($B276,Designs!$A$3:$AP$165,27,FALSE())),"") | N276: =IFERROR(IF(OR($I276="",$M276="",$M276=0),"",($I276-$M276)/$I276),"") | O276: 0 | P276: 0 | Q276: =IF($O276="","",$O276-IF($P276="",0,$P276)) -> 0 | R276: 2 | S276: =IF($O276="","",IF($Q276<=$R276,"⚠ REORDER","OK")) -> ⚠ REORDER | V276: 7117.19 | W276: Armenia | Z276: No | AA276: No | AB276: No | AC276: No | AD276: Active | AE276: =IFERROR(SUMIFS(Transactions!$F:$F,Transactions!$C:$C,$A276,Transactions!$D:$D,"Sale"),0) -> 0 | AF276: =IFERROR(SUMIFS(Transactions!$H:$H,Transactions!$C:$C,$A276,Transactions!$D:$D,"Sale"),0) -> 0 | AG276: =IFERROR(IF(maxifs(Transactions!$B:$B,Transactions!$C:$C,$A276,Transactions!$D:$D,"Sale")=0,"",maxifs(Transactions!$B:$B,Transactions!$C:$C,$A276,Transactions!$D:$D,"Sale")),"")
A277: KARNI-EARRNG-MARASH-M-TURQUOISE-BLUE | B277: DSGN-EARRNG-MARASH-M | C277: Marash Earrings | D277: Earring | E277: Marash | G277: medium | H277: turquoise-blue | I277: 27000 | J277: =IF($I277="","",ROUND($I277*Dropdowns!$K$5,2)) -> 70.2 | K277: =IF($I277="","",ROUND($I277*Dropdowns!$K$6,2)) -> 64.8 | L277: =IF($I277="","",ROUND($I277*Dropdowns!$K$7,2)) -> 5535 | M277: =IFERROR(IF($B277="","",VLOOKUP($B277,Designs!$A$3:$AP$165,27,FALSE())),"") | N277: =IFERROR(IF(OR($I277="",$M277="",$M277=0),"",($I277-$M277)/$I277),"") | O277: 0 | P277: 0 | Q277: =IF($O277="","",$O277-IF($P277="",0,$P277)) -> 0 | R277: 2 | S277: =IF($O277="","",IF($Q277<=$R277,"⚠ REORDER","OK")) -> ⚠ REORDER | V277: 7117.19 | W277: Armenia | Z277: No | AA277: No | AB277: No | AC277: No | AD277: Active | AE277: =IFERROR(SUMIFS(Transactions!$F:$F,Transactions!$C:$C,$A277,Transactions!$D:$D,"Sale"),0) -> 0 | AF277: =IFERROR(SUMIFS(Transactions!$H:$H,Transactions!$C:$C,$A277,Transactions!$D:$D,"Sale"),0) -> 0 | AG277: =IFERROR(IF(maxifs(Transactions!$B:$B,Transactions!$C:$C,$A277,Transactions!$D:$D,"Sale")=0,"",maxifs(Transactions!$B:$B,Transactions!$C:$C,$A277,Transactions!$D:$D,"Sale")),"")
A278: KARNI-EARRNG-VAN-S-BLUE | B278: DSGN-EARRNG-VAN-S | C278: Van Earrings | D278: Earring | E278: Van | G278: small | H278: blue | I278: 13000 | J278: =IF($I278="","",ROUND($I278*Dropdowns!$K$5,2)) -> 33.8 | K278: =IF($I278="","",ROUND($I278*Dropdowns!$K$6,2)) -> 31.2 | L278: =IF($I278="","",ROUND($I278*Dropdowns!$K$7,2)) -> 2665 | M278: =IFERROR(IF($B278="","",VLOOKUP($B278,Designs!$A$3:$AP$165,27,FALSE())),"") | N278: =IFERROR(IF(OR($I278="",$M278="",$M278=0),"",($I278-$M278)/$I278),"") | O278: 0 | P278: 0 | Q278: =IF($O278="","",$O278-IF($P278="",0,$P278)) -> 0 | R278: 2 | S278: =IF($O278="","",IF($Q278<=$R278,"⚠ REORDER","OK")) -> ⚠ REORDER | V278: 7117.19 | W278: Armenia | Z278: No | AA278: No | AB278: No | AC278: No | AD278: Active | AE278: =IFERROR(SUMIFS(Transactions!$F:$F,Transactions!$C:$C,$A278,Transactions!$D:$D,"Sale"),0) -> 0 | AF278: =IFERROR(SUMIFS(Transactions!$H:$H,Transactions!$C:$C,$A278,Transactions!$D:$D,"Sale"),0) -> 0 | AG278: =IFERROR(IF(maxifs(Transactions!$B:$B,Transactions!$C:$C,$A278,Transactions!$D:$D,"Sale")=0,"",maxifs(Transactions!$B:$B,Transactions!$C:$C,$A278,Transactions!$D:$D,"Sale")),"")
A279: KARNI-EARRNG-VAN-S-WHITE | B279: DSGN-EARRNG-VAN-S | C279: Van Earrings | D279: Earring | E279: Van | G279: small | H279: white | I279: 13000 | J279: =IF($I279="","",ROUND($I279*Dropdowns!$K$5,2)) -> 33.8 | K279: =IF($I279="","",ROUND($I279*Dropdowns!$K$6,2)) -> 31.2 | L279: =IF($I279="","",ROUND($I279*Dropdowns!$K$7,2)) -> 2665 | M279: =IFERROR(IF($B279="","",VLOOKUP($B279,Designs!$A$3:$AP$165,27,FALSE())),"") | N279: =IFERROR(IF(OR($I279="",$M279="",$M279=0),"",($I279-$M279)/$I279),"") | O279: 0 | P279: 0 | Q279: =IF($O279="","",$O279-IF($P279="",0,$P279)) -> 0 | R279: 2 | S279: =IF($O279="","",IF($Q279<=$R279,"⚠ REORDER","OK")) -> ⚠ REORDER | V279: 7117.19 | W279: Armenia | Z279: No | AA279: No | AB279: No | AC279: No | AD279: Active | AE279: =IFERROR(SUMIFS(Transactions!$F:$F,Transactions!$C:$C,$A279,Transactions!$D:$D,"Sale"),0) -> 0 | AF279: =IFERROR(SUMIFS(Transactions!$H:$H,Transactions!$C:$C,$A279,Transactions!$D:$D,"Sale"),0) -> 0 | AG279: =IFERROR(IF(maxifs(Transactions!$B:$B,Transactions!$C:$C,$A279,Transactions!$D:$D,"Sale")=0,"",maxifs(Transactions!$B:$B,Transactions!$C:$C,$A279,Transactions!$D:$D,"Sale")),"")
A280: KARNI-EARRNG-VAN-S-BORDEAUX | B280: DSGN-EARRNG-VAN-S | C280: Van Earrings | D280: Earring | E280: Van | G280: small | H280: bordeaux | I280: 13000 | J280: =IF($I280="","",ROUND($I280*Dropdowns!$K$5,2)) -> 33.8 | K280: =IF($I280="","",ROUND($I280*Dropdowns!$K$6,2)) -> 31.2 | L280: =IF($I280="","",ROUND($I280*Dropdowns!$K$7,2)) -> 2665 | M280: =IFERROR(IF($B280="","",VLOOKUP($B280,Designs!$A$3:$AP$165,27,FALSE())),"") | N280: =IFERROR(IF(OR($I280="",$M280="",$M280=0),"",($I280-$M280)/$I280),"") | O280: 0 | P280: 0 | Q280: =IF($O280="","",$O280-IF($P280="",0,$P280)) -> 0 | R280: 2 | S280: =IF($O280="","",IF($Q280<=$R280,"⚠ REORDER","OK")) -> ⚠ REORDER | V280: 7117.19 | W280: Armenia | Z280: No | AA280: No | AB280: No | AC280: No | AD280: Active | AE280: =IFERROR(SUMIFS(Transactions!$F:$F,Transactions!$C:$C,$A280,Transactions!$D:$D,"Sale"),0) -> 0 | AF280: =IFERROR(SUMIFS(Transactions!$H:$H,Transactions!$C:$C,$A280,Transactions!$D:$D,"Sale"),0) -> 0 | AG280: =IFERROR(IF(maxifs(Transactions!$B:$B,Transactions!$C:$C,$A280,Transactions!$D:$D,"Sale")=0,"",maxifs(Transactions!$B:$B,Transactions!$C:$C,$A280,Transactions!$D:$D,"Sale")),"")
... A314: KARNI-EARRNG-VISHABAREVAGORG-M-WHITE-BLUE-RED | B314: DSGN-EARRNG-VISHABAREVAGORG-M | C314: Արեւագորգի Վիշապ | D314: Earring | E314: Vishab Arevagorg | G314: medium | H314: white-blue-red | I314: 27000 | J314: =IF($I314="","",ROUND($I314*Dropdowns!$K$5,2)) -> 70.2 | K314: =IF($I314="","",ROUND($I314*Dropdowns!$K$6,2)) -> 64.8 | L314: =IF($I314="","",ROUND($I314*Dropdowns!$K$7,2)) -> 5535 | M314: =IFERROR(IF($B314="","",VLOOKUP($B314,Designs!$A$3:$AP$165,27,FALSE())),"") | N314: =IFERROR(IF(OR($I314="",$M314="",$M314=0),"",($I314-$M314)/$I314),"") | O314: 0 | P314: 0 | Q314: =IF($O314="","",$O314-IF($P314="",0,$P314)) -> 0 | R314: 2 | S314: =IF($O314="","",IF($Q314<=$R314,"⚠ REORDER","OK")) -> ⚠ REORDER | V314: 7117.19 | W314: Armenia | Z314: No | AA314: No | AB314: No | AC314: No | AD314: Active | AE314: =IFERROR(SUMIFS(Transactions!$F:$F,Transactions!$C:$C,$A314,Transactions!$D:$D,"Sale"),0) -> 0 | AF314: =IFERROR(SUMIFS(Transactions!$H:$H,Transactions!$C:$C,$A314,Transactions!$D:$D,"Sale"),0) -> 0 | AG314: =IFERROR(IF(maxifs(Transactions!$B:$B,Transactions!$C:$C,$A314,Transactions!$D:$D,"Sale")=0,"",maxifs(Transactions!$B:$B,Transactions!$C:$C,$A314,Transactions!$D:$D,"Sale")),"")
A315: KARNI-EARRNG2-MARASH-BLUE-WHITE | B315: DSGN-EARRNG2-MARASH | C315: Marash Earrings (2 pcs) | D315: earrings 2 pcs. | E315: Marash | H315: blue-white | I315: 36000 | J315: =IF($I315="","",ROUND($I315*Dropdowns!$K$5,2)) -> 93.6 | K315: =IF($I315="","",ROUND($I315*Dropdowns!$K$6,2)) -> 86.4 | L315: =IF($I315="","",ROUND($I315*Dropdowns!$K$7,2)) -> 7380 | M315: =IFERROR(IF($B315="","",VLOOKUP($B315,Designs!$A$3:$AP$165,27,FALSE())),"") | N315: =IFERROR(IF(OR($I315="",$M315="",$M315=0),"",($I315-$M315)/$I315),"") | O315: 0 | P315: 0 | Q315: =IF($O315="","",$O315-IF($P315="",0,$P315)) -> 0 | R315: 2 | S315: =IF($O315="","",IF($Q315<=$R315,"⚠ REORDER","OK")) -> ⚠ REORDER | V315: 7117.19 | W315: Armenia | Z315: No | AA315: No | AB315: No | AC315: No | AD315: Active | AE315: =IFERROR(SUMIFS(Transactions!$F:$F,Transactions!$C:$C,$A315,Transactions!$D:$D,"Sale"),0) -> 0 | AF315: =IFERROR(SUMIFS(Transactions!$H:$H,Transactions!$C:$C,$A315,Transactions!$D:$D,"Sale"),0) -> 0 | AG315: =IFERROR(IF(maxifs(Transactions!$B:$B,Transactions!$C:$C,$A315,Transactions!$D:$D,"Sale")=0,"",maxifs(Transactions!$B:$B,Transactions!$C:$C,$A315,Transactions!$D:$D,"Sale")),"")
A316: KARNI-EARRNG2-MARASH-WHITE-BLUE | B316: DSGN-EARRNG2-MARASH | C316: Marash Earrings (2 pcs) | D316: earrings 2 pcs. | E316: Marash | H316: white-blue | I316: 36000 | J316: =IF($I316="","",ROUND($I316*Dropdowns!$K$5,2)) -> 93.6 | K316: =IF($I316="","",ROUND($I316*Dropdowns!$K$6,2)) -> 86.4 | L316: =IF($I316="","",ROUND($I316*Dropdowns!$K$7,2)) -> 7380 | M316: =IFERROR(IF($B316="","",VLOOKUP($B316,Designs!$A$3:$AP$165,27,FALSE())),"") | N316: =IFERROR(IF(OR($I316="",$M316="",$M316=0),"",($I316-$M316)/$I316),"") | O316: 0 | P316: 0 | Q316: =IF($O316="","",$O316-IF($P316="",0,$P316)) -> 0 | R316: 2 | S316: =IF($O316="","",IF($Q316<=$R316,"⚠ REORDER","OK")) -> ⚠ REORDER | V316: 7117.19 | W316: Armenia | Z316: No | AA316: No | AB316: No | AC316: No | AD316: Active | AE316: =IFERROR(SUMIFS(Transactions!$F:$F,Transactions!$C:$C,$A316,Transactions!$D:$D,"Sale"),0) -> 0 | AF316: =IFERROR(SUMIFS(Transactions!$H:$H,Transactions!$C:$C,$A316,Transactions!$D:$D,"Sale"),0) -> 0 | AG316: =IFERROR(IF(maxifs(Transactions!$B:$B,Transactions!$C:$C,$A316,Transactions!$D:$D,"Sale")=0,"",maxifs(Transactions!$B:$B,Transactions!$C:$C,$A316,Transactions!$D:$D,"Sale")),"")
A317: KARNI-EARRNG2-MARASH-WHITE-BORDEAUX | B317: DSGN-EARRNG2-MARASH | C317: Marash Earrings (2 pcs) | D317: earrings 2 pcs. | E317: Marash | H317: white-bordeaux | I317: 36000 | J317: =IF($I317="","",ROUND($I317*Dropdowns!$K$5,2)) -> 93.6 | K317: =IF($I317="","",ROUND($I317*Dropdowns!$K$6,2)) -> 86.4 | L317: =IF($I317="","",ROUND($I317*Dropdowns!$K$7,2)) -> 7380 | M317: =IFERROR(IF($B317="","",VLOOKUP($B317,Designs!$A$3:$AP$165,27,FALSE())),"") | N317: =IFERROR(IF(OR($I317="",$M317="",$M317=0),"",($I317-$M317)/$I317),"") | O317: 0 | P317: 0 | Q317: =IF($O317="","",$O317-IF($P317="",0,$P317)) -> 0 | R317: 2 | S317: =IF($O317="","",IF($Q317<=$R317,"⚠ REORDER","OK")) -> ⚠ REORDER | V317: 7117.19 | W317: Armenia | Z317: No | AA317: No | AB317: No | AC317: No | AD317: Active | AE317: =IFERROR(SUMIFS(Transactions!$F:$F,Transactions!$C:$C,$A317,Transactions!$D:$D,"Sale"),0) -> 0 | AF317: =IFERROR(SUMIFS(Transactions!$H:$H,Transactions!$C:$C,$A317,Transactions!$D:$D,"Sale"),0) -> 0 | AG317: =IFERROR(IF(maxifs(Transactions!$B:$B,Transactions!$C:$C,$A317,Transactions!$D:$D,"Sale")=0,"",maxifs(Transactions!$B:$B,Transactions!$C:$C,$A317,Transactions!$D:$D,"Sale")),"")
A318: KARNI-EARRNG2-MARASH-TURQUOISE-BLUE | B318: DSGN-EARRNG2-MARASH | C318: Marash Earrings (2 pcs) | D318: earrings 2 pcs. | E318: Marash | H318: turquoise-blue | I318: 36000 | J318: =IF($I318="","",ROUND($I318*Dropdowns!$K$5,2)) -> 93.6 | K318: =IF($I318="","",ROUND($I318*Dropdowns!$K$6,2)) -> 86.4 | L318: =IF($I318="","",ROUND($I318*Dropdowns!$K$7,2)) -> 7380 | M318: =IFERROR(IF($B318="","",VLOOKUP($B318,Designs!$A$3:$AP$165,27,FALSE())),"") | N318: =IFERROR(IF(OR($I318="",$M318="",$M318=0),"",($I318-$M318)/$I318),"") | O318: 0 | P318: 0 | Q318: =IF($O318="","",$O318-IF($P318="",0,$P318)) -> 0 | R318: 2 | S318: =IF($O318="","",IF($Q318<=$R318,"⚠ REORDER","OK")) -> ⚠ REORDER | V318: 7117.19 | W318: Armenia | Z318: No | AA318: No | AB318: No | AC318: No | AD318: Active | AE318: =IFERROR(SUMIFS(Transactions!$F:$F,Transactions!$C:$C,$A318,Transactions!$D:$D,"Sale"),0) -> 0 | AF318: =IFERROR(SUMIFS(Transactions!$H:$H,Transactions!$C:$C,$A318,Transactions!$D:$D,"Sale"),0) -> 0 | AG318: =IFERROR(IF(maxifs(Transactions!$B:$B,Transactions!$C:$C,$A318,Transactions!$D:$D,"Sale")=0,"",maxifs(Transactions!$B:$B,Transactions!$C:$C,$A318,Transactions!$D:$D,"Sale")),"")
A319: KARNI-EARRNG2-VISHAB-BLUE-WHITE | B319: DSGN-EARRNG2-VISHAB | C319: Vishab Earrings (2 pcs) | D319: earrings 2 pcs. | E319: Vishab | H319: blue-white | I319: 36000 | J319: =IF($I319="","",ROUND($I319*Dropdowns!$K$5,2)) -> 93.6 | K319: =IF($I319="","",ROUND($I319*Dropdowns!$K$6,2)) -> 86.4 | L319: =IF($I319="","",ROUND($I319*Dropdowns!$K$7,2)) -> 7380 | M319: =IFERROR(IF($B319="","",VLOOKUP($B319,Designs!$A$3:$AP$165,27,FALSE())),"") | N319: =IFERROR(IF(OR($I319="",$M319="",$M319=0),"",($I319-$M319)/$I319),"") | O319: 0 | P319: 0 | Q319: =IF($O319="","",$O319-IF($P319="",0,$P319)) -> 0 | R319: 2 | S319: =IF($O319="","",IF($Q319<=$R319,"⚠ REORDER","OK")) -> ⚠ REORDER | V319: 7117.19 | W319: Armenia | Z319: No | AA319: No | AB319: No | AC319: No | AD319: Active | AE319: =IFERROR(SUMIFS(Transactions!$F:$F,Transactions!$C:$C,$A319,Transactions!$D:$D,"Sale"),0) -> 0 | AF319: =IFERROR(SUMIFS(Transactions!$H:$H,Transactions!$C:$C,$A319,Transactions!$D:$D,"Sale"),0) -> 0 | AG319: =IFERROR(IF(maxifs(Transactions!$B:$B,Transactions!$C:$C,$A319,Transactions!$D:$D,"Sale")=0,"",maxifs(Transactions!$B:$B,Transactions!$C:$C,$A319,Transactions!$D:$D,"Sale")),"")
A320: KARNI-EARRNG2-VISHAB-BLUE-RED | B320: DSGN-EARRNG2-VISHAB | C320: Vishab Earrings (2 pcs) | D320: earrings 2 pcs. | E320: Vishab | H320: blue-red | I320: 36000 | J320: =IF($I320="","",ROUND($I320*Dropdowns!$K$5,2)) -> 93.6 | K320: =IF($I320="","",ROUND($I320*Dropdowns!$K$6,2)) -> 86.4 | L320: =IF($I320="","",ROUND($I320*Dropdowns!$K$7,2)) -> 7380 | M320: =IFERROR(IF($B320="","",VLOOKUP($B320,Designs!$A$3:$AP$165,27,FALSE())),"") | N320: =IFERROR(IF(OR($I320="",$M320="",$M320=0),"",($I320-$M320)/$I320),"") | O320: 0 | P320: 0 | Q320: =IF($O320="","",$O320-IF($P320="",0,$P320)) -> 0 | R320: 2 | S320: =IF($O320="","",IF($Q320<=$R320,"⚠ REORDER","OK")) -> ⚠ REORDER | V320: 7117.19 | W320: Armenia | Z320: No | AA320: No | AB320: No | AC320: No | AD320: Active | AE320: =IFERROR(SUMIFS(Transactions!$F:$F,Transactions!$C:$C,$A320,Transactions!$D:$D,"Sale"),0) -> 0 | AF320: =IFERROR(SUMIFS(Transactions!$H:$H,Transactions!$C:$C,$A320,Transactions!$D:$D,"Sale"),0) -> 0 | AG320: =IFERROR(IF(maxifs(Transactions!$B:$B,Transactions!$C:$C,$A320,Transactions!$D:$D,"Sale")=0,"",maxifs(Transactions!$B:$B,Transactions!$C:$C,$A320,Transactions!$D:$D,"Sale")),"")
A321: KARNI-EARRNG2-VISHAB-WHITE-BORDEAUX | B321: DSGN-EARRNG2-VISHAB | C321: Vishab Earrings (2 pcs) | D321: earrings 2 pcs. | E321: Vishab | H321: white-bordeaux | I321: 36000 | J321: =IF($I321="","",ROUND($I321*Dropdowns!$K$5,2)) -> 93.6 | K321: =IF($I321="","",ROUND($I321*Dropdowns!$K$6,2)) -> 86.4 | L321: =IF($I321="","",ROUND($I321*Dropdowns!$K$7,2)) -> 7380 | M321: =IFERROR(IF($B321="","",VLOOKUP($B321,Designs!$A$3:$AP$165,27,FALSE())),"") | N321: =IFERROR(IF(OR($I321="",$M321="",$M321=0),"",($I321-$M321)/$I321),"") | O321: 0 | P321: 0 | Q321: =IF($O321="","",$O321-IF($P321="",0,$P321)) -> 0 | R321: 2 | S321: =IF($O321="","",IF($Q321<=$R321,"⚠ REORDER","OK")) -> ⚠ REORDER | V321: 7117.19 | W321: Armenia | Z321: No | AA321: No | AB321: No | AC321: No | AD321: Active | AE321: =IFERROR(SUMIFS(Transactions!$F:$F,Transactions!$C:$C,$A321,Transactions!$D:$D,"Sale"),0) -> 0 | AF321: =IFERROR(SUMIFS(Transactions!$H:$H,Transactions!$C:$C,$A321,Transactions!$D:$D,"Sale"),0) -> 0 | AG321: =IFERROR(IF(maxifs(Transactions!$B:$B,Transactions!$C:$C,$A321,Transactions!$D:$D,"Sale")=0,"",maxifs(Transactions!$B:$B,Transactions!$C:$C,$A321,Transactions!$D:$D,"Sale")),"")
A322: KARNI-EARRNG2-VISHAB-TURQUOISE-BLUE | B322: DSGN-EARRNG2-VISHAB | C322: Vishab Earrings (2 pcs) | D322: earrings 2 pcs. | E322: Vishab | H322: turquoise-blue | I322: 36000 | J322: =IF($I322="","",ROUND($I322*Dropdowns!$K$5,2)) -> 93.6 | K322: =IF($I322="","",ROUND($I322*Dropdowns!$K$6,2)) -> 86.4 | L322: =IF($I322="","",ROUND($I322*Dropdowns!$K$7,2)) -> 7380 | M322: =IFERROR(IF($B322="","",VLOOKUP($B322,Designs!$A$3:$AP$165,27,FALSE())),"") | N322: =IFERROR(IF(OR($I322="",$M322="",$M322=0),"",($I322-$M322)/$I322),"") | O322: 0 | P322: 0 | Q322: =IF($O322="","",$O322-IF($P322="",0,$P322)) -> 0 | R322: 2 | S322: =IF($O322="","",IF($Q322<=$R322,"⚠ REORDER","OK")) -> ⚠ REORDER | V322: 7117.19 | W322: Armenia | Z322: No | AA322: No | AB322: No | AC322: No | AD322: Active | AE322: =IFERROR(SUMIFS(Transactions!$F:$F,Transactions!$C:$C,$A322,Transactions!$D:$D,"Sale"),0) -> 0 | AF322: =IFERROR(SUMIFS(Transactions!$H:$H,Transactions!$C:$C,$A322,Transactions!$D:$D,"Sale"),0) -> 0 | AG322: =IFERROR(IF(maxifs(Transactions!$B:$B,Transactions!$C:$C,$A322,Transactions!$D:$D,"Sale")=0,"",maxifs(Transactions!$B:$B,Transactions!$C:$C,$A322,Transactions!$D:$D,"Sale")),"")
A323: KARNI-EARRNG2-VAN-WHITE | B323: DSGN-EARRNG2-VAN | C323: Van Earrings (2 pcs) | D323: earrings 2 pcs. | E323: Van | H323: white | I323: 36000 | J323: =IF($I323="","",ROUND($I323*Dropdowns!$K$5,2)) -> 93.6 | K323: =IF($I323="","",ROUND($I323*Dropdowns!$K$6,2)) -> 86.4 | L323: =IF($I323="","",ROUND($I323*Dropdowns!$K$7,2)) -> 7380 | M323: =IFERROR(IF($B323="","",VLOOKUP($B323,Designs!$A$3:$AP$165,27,FALSE())),"") | N323: =IFERROR(IF(OR($I323="",$M323="",$M323=0),"",($I323-$M323)/$I323),"") | O323: 0 | P323: 0 | Q323: =IF($O323="","",$O323-IF($P323="",0,$P323)) -> 0 | R323: 2 | S323: =IF($O323="","",IF($Q323<=$R323,"⚠ REORDER","OK")) -> ⚠ REORDER | V323: 7117.19 | W323: Armenia | Z323: No | AA323: No | AB323: No | AC323: No | AD323: Active | AE323: =IFERROR(SUMIFS(Transactions!$F:$F,Transactions!$C:$C,$A323,Transactions!$D:$D,"Sale"),0) -> 0 | AF323: =IFERROR(SUMIFS(Transactions!$H:$H,Transactions!$C:$C,$A323,Transactions!$D:$D,"Sale"),0) -> 0 | AG323: =IFERROR(IF(maxifs(Transactions!$B:$B,Transactions!$C:$C,$A323,Transactions!$D:$D,"Sale")=0,"",maxifs(Transactions!$B:$B,Transactions!$C:$C,$A323,Transactions!$D:$D,"Sale")),"")
A324: KARNI-EARRNG2-VAN-BLUE | B324: DSGN-EARRNG2-VAN | C324: Van Earrings (2 pcs) | D324: earrings 2 pcs. | E324: Van | H324: blue | I324: 36000 | J324: =IF($I324="","",ROUND($I324*Dropdowns!$K$5,2)) -> 93.6 | K324: =IF($I324="","",ROUND($I324*Dropdowns!$K$6,2)) -> 86.4 | L324: =IF($I324="","",ROUND($I324*Dropdowns!$K$7,2)) -> 7380 | M324: =IFERROR(IF($B324="","",VLOOKUP($B324,Designs!$A$3:$AP$165,27,FALSE())),"") | N324: =IFERROR(IF(OR($I324="",$M324="",$M324=0),"",($I324-$M324)/$I324),"") | O324: 0 | P324: 0 | Q324: =IF($O324="","",$O324-IF($P324="",0,$P324)) -> 0 | R324: 2 | S324: =IF($O324="","",IF($Q324<=$R324,"⚠ REORDER","OK")) -> ⚠ REORDER | V324: 7117.19 | W324: Armenia | Z324: No | AA324: No | AB324: No | AC324: No | AD324: Active | AE324: =IFERROR(SUMIFS(Transactions!$F:$F,Transactions!$C:$C,$A324,Transactions!$D:$D,"Sale"),0) -> 0 | AF324: =IFERROR(SUMIFS(Transactions!$H:$H,Transactions!$C:$C,$A324,Transactions!$D:$D,"Sale"),0) -> 0 | AG324: =IFERROR(IF(maxifs(Transactions!$B:$B,Transactions!$C:$C,$A324,Transactions!$D:$D,"Sale")=0,"",maxifs(Transactions!$B:$B,Transactions!$C:$C,$A324,Transactions!$D:$D,"Sale")),"")
